Workbook

Sheet Kalkulation
A1: =D12 -> 22800
B2: Privat | C2: p.m. | D2: p.a. | F2: Tage gesamt | G2: pro | H2: Jahr | I2: 365
B3: Lebenshaltung | C3: 250 | D3: =C3*12 -> 3000 | F3: Urlaub | G3: pro | H3: Jahr | I3: -20
B4: KV | C4: 400 | D4: =C4*12 -> 4800 | F4: Feiertage | G4: pro | H4: Jahr | I4: -11
B5: RV | C5: 300 | D5: =C5*12 -> 3600 | F5: Wochenende | G5: pro | H5: Jahr | I5: -104
B6: Miete | C6: 400 | D6: =C6*12 -> 4800 | F6: Weiterbildungen | G6: pro | H6: Jahr | I6: -5
B7: Freizeit | C7: 300 | D7: =C7*12 -> 3600 | F7: Krank | G7: pro | H7: Jahr | I7: -5
B8: Sonstiges | C8: 250 | D8: =C8*12 -> 3000 | F8: Büro/Orga | G8: pro | H8: Jahr | I8: -26
F9: Produktive Tage | G9: pro | H9: Jahr | I9: =SUM(I2:I8) -> 194
F10: Produktive Tage gerundet | G10: pro | H10: Monat | I10: =I9/12 -> 16.166667
D11: =C11*12 -> 0 | F11: produktive Stunden | G11: pro | H11: Monat | I11: =I10*8 -> 129.33333
B12: Summe | C12: =SUM(C3:C11) -> 1900 | D12: =SUM(D3:D11) -> 22800
F13: Gewinn | G13: 0.05
B14: EK Steuer | C14: p.m | D14: p.a. | F14: Risiko | G14: 0.05
B15: 2025 | C15: =D15/12 -> 192.75 | D15: =IF(D12<=12096, 0, IF(D12<=17443, ROUNDDOWN( ( ( ( (D12-12096) / 10000 ) * 979 ) + 1400 ) * ( (D12-12096)/10000 ),0 ), IF(D12<=68480, ROUNDDOWN( ( ( ( (D12-17443) / 10000 ) * 223 ) + 2397 ) * ( (D12-17443)/10000 ) + 965.58,0 ), IF(D12<=277825, ROUNDDOWN( 0.42*D12-9972.48,0 ), ROUNDDOWN(0.45*D12-17098.98,0 ))))) -> 2313 | F15: Wohlfühlzuschlag | G15: 0.1
B17: Unternehmen | C17: p.m. | D17: p.a. | G17: p.m. | H17: p.a.
B18: Miete | C18: 400 | D18: =C18*12 -> 4800 | F18: min Umsatz | G18: =C12+C15+C36 -> 5842.75 | H18: =D12+D15+D36 -> 70113
B19: Nebenkosten | C19: 150 | D19: =C19*12 -> 1800 | F19: Gewinn | G19: =G18*G13 -> 292.1375 | H19: =G19*12 -> 3505.65
B20: Fahrzeug | C20: 200 | D20: =C20*12 -> 2400 | F20: Risiko | G20: =G18*G14 -> 292.1375 | H20: =G20*12 -> 3505.65
B21: Werbekosten | C21: 2000 | D21: =C21*12 -> 24000 | F21: Wohlfühlzuschlag | G21: =G18*G15 -> 584.275 | H21: =G21*12 -> 7011.3
B22: Reisekosten | C22: 100 | D22: =C22*12 -> 1200 | F22: Soll | G22: =SUM(G18:G21) -> 7011.3 | H22: =SUM(H18:H21) -> 84135.6
B23: Kommunikation | C23: 100 | D23: =C23*12 -> 1200
B24: Versicherungen/Gebühren | C24: 100 | D24: =C24*12 -> 1200 | G24: netto | H24: brutto
B25: Beratung | C25: 150 | D25: =C25*12 -> 1800 | F25: Tagesumsatz | G25: =G22/I10 -> 433.68866 | H25: =G25*1.19 -> 516.08951
B26: Leasing | C26: 250 | D26: =C26*12 -> 3000 | F26: Stundensatz | G26: =G22/I11 -> 54.211082 | H26: =G26*1.19 -> 64.511188
B27: Lizenzen | C27: 100 | D27: =C27*12 -> 1200 | F27: Anzahl nutzer
D28: =C28*12 -> 0
D29: =C29*12 -> 0
B30: Sonstige | C30: 200 | D30: =C30*12 -> 2400
D34: =C34*12 -> 0
D35: =C35*12 -> 0
B36: Summe | C36: =SUM(C18:C35) -> 3750 | D36: =SUM(D18:D35) -> 45000

Sheet 2 Gründer
A1: GRÜNDER 1 - Privatkosten | B1: p.m. | C1: p.a.
A2: Lebenshaltung | B2: 250 | C2: =B2*12 -> 3000
A3: Krankenversicherung | B3: 400 | C3: =B3*12 -> 4800
A4: Rentenversicherung | B4: 300 | C4: =B4*12 -> 3600
A5: Miete (privat) | B5: 400 | C5: =B5*12 -> 4800
A6: Freizeit | B6: 300 | C6: =B6*12 -> 3600
A7: Sonstiges | B7: 250 | C7: =B7*12 -> 3000
A8: Summe Gründer 1 | B8: =SUM(B2:B7) -> 1900 | C8: =SUM(C2:C7) -> 22800
A9: EK-Steuer Gründer 1 (2025) | B9: =C9/12 -> 192.75 | C9: =IF(C8<=12096,0,IF(C8<=17443,ROUNDDOWN((((C8-12096)/10000)*979+1400)*((C8-12096)/10000),0),IF(C8<=68480,ROUNDDOWN((((C8-17443)/10000)*223+2397)*((C8-17443)/10000)+965.58,0),IF(C8<=277825,ROUNDDOWN(0.42*C8-9972.48,0),ROUNDDOWN(0.45*C8-17098.98,0))))) -> 2313
A11: GRÜNDER 2 - Privatkosten | B11: p.m. | C11: p.a.
A12: Lebenshaltung | B12: 250 | C12: =B12*12 -> 3000
A13: Krankenversicherung | B13: 400 | C13: =B13*12 -> 4800
A14: Rentenversicherung | B14: 300 | C14: =B14*12 -> 3600
A15: Miete (privat) | B15: 400 | C15: =B15*12 -> 4800
A16: Freizeit | B16: 300 | C16: =B16*12 -> 3600
A17: Sonstiges | B17: 250 | C17: =B17*12 -> 3000
A18: Summe Gründer 2 | B18: =SUM(B12:B17) -> 1900 | C18: =SUM(C12:C17) -> 22800
A19: EK-Steuer Gründer 2 (2025) | B19: =C19/12 -> 192.75 | C19: =IF(C18<=12096,0,IF(C18<=17443,ROUNDDOWN((((C18-12096)/10000)*979+1400)*((C18-12096)/10000),0),IF(C18<=68480,ROUNDDOWN((((C18-17443)/10000)*223+2397)*((C18-17443)/10000)+965.58,0),IF(C18<=277825,ROUNDDOWN(0.42*C18-9972.48,0),ROUNDDOWN(0.45*C18-17098.98,0))))) -> 2313
A21: UNTERNEHMENSKOSTEN | B21: p.m. | C21: p.a.
A22: Büro/Miete | B22: 400 | C22: =B22*12 -> 4800
A23: Nebenkosten | B23: 150 | C23: =B23*12 -> 1800
A24: Fahrzeug | B24: 200 | C24: =B24*12 -> 2400
A25: Werbekosten/Marketing | B25: 2000 | C25: =B25*12 -> 24000
A26: Reisekosten | B26: 100 | C26: =B26*12 -> 1200
A27: Kommunikation | B27: 100 | C27: =B27*12 -> 1200
A28: Versicherungen/Gebühren | B28: 100 | C28: =B28*12 -> 1200
A29: Steuerberatung | B29: 150 | C29: =B29*12 -> 1800
A30: Leasing/Hardware | B30: 250 | C30: =B30*12 -> 3000
A31: Lizenzen/Software | B31: 100 | C31: =B31*12 -> 1200
A32: Server/Hosting (Supabase etc.) | B32: 50 | C32: =B32*12 -> 600
A33: Sonstige | B33: 200 | C33: =B33*12 -> 2400
A34: Summe Unternehmen | B34: =SUM(B22:B33) -> 3800 | C34: =SUM(C22:C33) -> 45600
A36: GESAMTÜBERSICHT 2 GRÜNDER | B36: p.m. | C36: p.a. | F36: ZUSCHLÄGE | H36: Satz
A37: Privatkosten Gründer 1 | B37: =B8+B9 -> 2092.75 | C37: =C8+C9 -> 25113 | F37: Gewinnmarge | H37: 0.05
A38: Privatkosten Gründer 2 | B38: =B18+B19 -> 2092.75 | C38: =C18+C19 -> 25113 | F38: Risikopuffer | H38: 0.05
A39: Unternehmenskosten | B39: =B34 -> 3800 | C39: =C34 -> 45600 | F39: Wohlfühlzuschlag | H39: 0.1
A40: Gesamtkosten (Basis) | B40: =SUM(B37:B39) -> 7985.5 | C40: =SUM(C37:C39) -> 95826
A41: + Gewinnmarge (5%) | B41: =B40*H37 -> 399.275 | C41: =C40*H37 -> 4791.3
A42: + Risikopuffer (5%) | B42: =B40*H38 -> 399.275 | C42: =C40*H38 -> 4791.3
A43: + Wohlfühlzuschlag (10%) | B43: =B40*H39 -> 798.55 | C43: =C40*H39 -> 9582.6
...

Sheet Erlösmodell
A1: ANNAHMEN - ERLÖSSTRÖME | C1: Wert | F1: ERLÖS-AUFTEILUNG BEI 10.000 NUTZERN
A2: Premium-Abo Preis (€/Monat) | C2: 4.5 | F2: Premium-Nutzer (Anzahl) | H2: =10000*C3 -> 500
A3: Free-to-Premium Conversion Rate | C3: 0.05 | F3: Free-Nutzer (Anzahl) | H3: =10000*(1-C3) -> 9500
A4: Monatliche Churn Rate (Premium) | C4: 0.03
A5: Affiliate Erlös pro Klick (€) | C5: 0.08 | F5: Premium-Abo Einnahmen | H5: =H2*C2 -> 2250
A6: Klicks pro aktivem Nutzer/Monat | C6: 12 | F6: Affiliate Einnahmen | H6: =H3*C5*C6 -> 9120
A7: Werbeeinnahmen pro 1000 Views (CPM, €) | C7: 3.5 | F7: Werbe-Einnahmen | H7: =H3*C7*C8/1000 -> 1995
A8: Ad-Views pro Nutzer/Monat (Free) | C8: 60 | F8: Gesponserte Rezepte | H8: =C9*C10 -> 0
A9: Gesponserte Rezepte (€/Stück/Monat) | C9: 500
A10: Anzahl gesponserter Rezepte | C10: 0 | F10: Gesamterlös p.m. bei 10k Nutzern | H10: =SUM(H5:H8) -> 13365
A13: ERLÖS PRO NUTZER / MONAT
A14: Premium-Nutzer Erlös | C14: =C2 -> 4.5
A15: Free-Nutzer Affiliate-Erlös | C15: =C5*C6 -> 0.96
A16: Free-Nutzer Werbe-Erlös | C16: =C8/1000*C7 -> 0.21
A17: Ø Erlös pro Nutzer (gewichtet) | C17: =C3*C14 + (1-C3)*(C15+C16) -> 1.3365
A19: BREAK-EVEN ANALYSE
A20: Soll-Umsatz p.m. (1 Gründer) | C20: ='2 Gründer'!B45/2 -> 4791.3
A21: Soll-Umsatz p.m. (2 Gründer) | C21: ='2 Gründer'!B45 -> 9582.6
A23: Benötigte aktive Nutzer (1 Gründer) | C23: =ROUNDUP(C20/C17,0) -> 3585
A24: Benötigte aktive Nutzer (2 Gründer) | C24: =ROUNDUP(C21/C17,0) -> 7170

Sheet Skalierung 24 Monate
A1: Monat | B1: Neue Nutzer | C1: Gesamt Nutzer | D1: Aktive Nutzer (80%) | E1: Premium Nutzer | F1: Free Nutzer | G1: Erlös Premium (€) | H1: Erlös Affiliate (€) | I1: Erlös Werbung (€) | J1: Erlös Gesponsert (€) | K1: Gesamterlös (€) | L1: Kosten (€) | M1: Gewinn/Verlust (€) | N1: Kumuliert (€)
B2: Annahme: | D2: 80% aktiv | E2: =Erlösmodell!C3 -> 0.05 | G2: =Erlösmodell!C2 -> 4.5 | H2: =Erlösmodell!C5*Erlösmodell!C6 -> 0.96 | I2: =Erlösmodell!C7*Erlösmodell!C8/1000 -> 0.21 | J2: =Erlösmodell!C9*Erlösmodell!C10 -> 0 | L2: ='2 Gründer'!B45 -> 9582.6
A3: 1 | B3: 150 | C3: =B3 -> 150 | D3: =ROUND(C3*0.8,0) -> 120 | E3: =ROUND(D3*$E$2,0) -> 6 | F3: =D3-E3 -> 114 | G3: =E3*$G$2 -> 27 | H3: =F3*$H$2 -> 109.44 | I3: =F3*$I$2 -> 23.94 | J3: =$J$2 -> 0 | K3: =SUM(G3:J3) -> 160.38 | L3: =$L$2 -> 9582.6 | M3: =K3-L3 -> -9422.22 | N3: =M3 -> -9422.22
A4: 2 | B4: =ROUND(B3*(1.3-(2-1)*0.008),0) -> 194 | C4: =ROUND(C3*0.98+B4,0) -> 341 | D4: =ROUND(C4*0.8,0) -> 273 | E4: =ROUND(D4*$E$2,0) -> 14 | F4: =D4-E4 -> 259 | G4: =E4*$G$2 -> 63 | H4: =F4*$H$2 -> 248.64 | I4: =F4*$I$2 -> 54.39 | J4: =$J$2 -> 0 | K4: =SUM(G4:J4) -> 366.03 | L4: =$L$2 -> 9582.6 | M4: =K4-L4 -> -9216.57 | N4: =N3+M4 -> -18638.79
A5: 3 | B5: =ROUND(B4*(1.3-(3-1)*0.008),0) -> 249 | C5: =ROUND(C4*0.98+B5,0) -> 583 | D5: =ROUND(C5*0.8,0) -> 466 | E5: =ROUND(D5*$E$2,0) -> 23 | F5: =D5-E5 -> 443 | G5: =E5*$G$2 -> 103.5 | H5: =F5*$H$2 -> 425.28 | I5: =F5*$I$2 -> 93.03 | J5: =$J$2 -> 0 | K5: =SUM(G5:J5) -> 621.81 | L5: =$L$2 -> 9582.6 | M5: =K5-L5 -> -8960.79 | N5: =N4+M5 -> -27599.58
A6: 4 | B6: =ROUND(B5*(1.3-(4-1)*0.008),0) -> 318 | C6: =ROUND(C5*0.98+B6,0) -> 889 | D6: =ROUND(C6*0.8,0) -> 711 | E6: =ROUND(D6*$E$2,0) -> 36 | F6: =D6-E6 -> 675 | G6: =E6*$G$2 -> 162 | H6: =F6*$H$2 -> 648 | I6: =F6*$I$2 -> 141.75 | J6: =$J$2 -> 0 | K6: =SUM(G6:J6) -> 951.75 | L6: =$L$2 -> 9582.6 | M6: =K6-L6 -> -8630.85 | N6: =N5+M6 -> -36230.43
A7: 5 | B7: =ROUND(B6*(1.3-(5-1)*0.008),0) -> 403 | C7: =ROUND(C6*0.98+B7,0) -> 1274 | D7: =ROUND(C7*0.8,0) -> 1019 | E7: =ROUND(D7*$E$2,0) -> 51 | F7: =D7-E7 -> 968 | G7: =E7*$G$2 -> 229.5 | H7: =F7*$H$2 -> 929.28 | I7: =F7*$I$2 -> 203.28 | J7: =$J$2 -> 0 | K7: =SUM(G7:J7) -> 1362.06 | L7: =$L$2 -> 9582.6 | M7: =K7-L7 -> -8220.54 | N7: =N6+M7 -> -44450.97
A8: 6 | B8: =ROUND(B7*(1.3-(6-1)*0.008),0) -> 508 | C8: =ROUND(C7*0.98+B8,0) -> 1757 | D8: =ROUND(C8*0.8,0) -> 1406 | E8: =ROUND(D8*$E$2,0) -> 70 | F8: =D8-E8 -> 1336 | G8: =E8*$G$2 -> 315 | H8: =F8*$H$2 -> 1282.56 | I8: =F8*$I$2 -> 280.56 | J8: =$J$2 -> 0 | K8: =SUM(G8:J8) -> 1878.12 | L8: =$L$2 -> 9582.6 | M8: =K8-L8 -> -7704.48 | N8: =N7+M8 -> -52155.45
A9: 7 | B9: =ROUND(B8*(1.3-(7-1)*0.008),0) -> 636 | C9: =ROUND(C8*0.98+B9,0) -> 2358 | D9: =ROUND(C9*0.8,0) -> 1886 | E9: =ROUND(D9*$E$2,0) -> 94 | F9: =D9-E9 -> 1792 | G9: =E9*$G$2 -> 423 | H9: =F9*$H$2 -> 1720.32 | I9: =F9*$I$2 -> 376.32 | J9: =$J$2 -> 0 | K9: =SUM(G9:J9) -> 2519.64 | L9: =$L$2 -> 9582.6 | M9: =K9-L9 -> -7062.96 | N9: =N8+M9 -> -59218.41
A10: 8 | B10: =ROUND(B9*(1.3-(8-1)*0.008),0) -> 791 | C10: =ROUND(C9*0.98+B10,0) -> 3102 | D10: =ROUND(C10*0.8,0) -> 2482 | E10: =ROUND(D10*$E$2,0) -> 124 | F10: =D10-E10 -> 2358 | G10: =E10*$G$2 -> 558 | H10: =F10*$H$2 -> 2263.68 | I10: =F10*$I$2 -> 495.18 | J10: =$J$2 -> 0 | K10: =SUM(G10:J10) -> 3316.86 | L10: =$L$2 -> 9582.6 | M10: =K10-L10 -> -6265.74 | N10: =N9+M10 -> -65484.15
A11: 9 | B11: =ROUND(B10*(1.3-(9-1)*0.008),0) -> 978 | C11: =ROUND(C10*0.98+B11,0) -> 4018 | D11: =ROUND(C11*0.8,0) -> 3214 | E11: =ROUND(D11*$E$2,0) -> 161 | F11: =D11-E11 -> 3053 | G11: =E11*$G$2 -> 724.5 | H11: =F11*$H$2 -> 2930.88 | I11: =F11*$I$2 -> 641.13 | J11: =$J$2 -> 0 | K11: =SUM(G11:J11) -> 4296.51 | L11: =$L$2 -> 9582.6 | M11: =K11-L11 -> -5286.09 | N11: =N10+M11 -> -70770.24
A12: 10 | B12: =ROUND(B11*(1.3-(10-1)*0.008),0) -> 1201 | C12: =ROUND(C11*0.98+B12,0) -> 5139 | D12: =ROUND(C12*0.8,0) -> 4111 | E12: =ROUND(D12*$E$2,0) -> 206 | F12: =D12-E12 -> 3905 | G12: =E12*$G$2 -> 927 | H12: =F12*$H$2 -> 3748.8 | I12: =F12*$I$2 -> 820.05 | J12: =$J$2 -> 0 | K12: =SUM(G12:J12) -> 5495.85 | L12: =$L$2 -> 9582.6 | M12: =K12-L12 -> -4086.75 | N12: =N11+M12 -> -74856.99
A13: 11 | B13: =ROUND(B12*(1.3-(11-1)*0.008),0) -> 1465 | C13: =ROUND(C12*0.98+B13,0) -> 6501 | D13: =ROUND(C13*0.8,0) -> 5201 | E13: =ROUND(D13*$E$2,0) -> 260 | F13: =D13-E13 -> 4941 | G13: =E13*$G$2 -> 1170 | H13: =F13*$H$2 -> 4743.36 | I13: =F13*$I$2 -> 1037.61 | J13: =$J$2 -> 0 | K13: =SUM(G13:J13) -> 6950.97 | L13: =$L$2 -> 9582.6 | M13: =K13-L13 -> -2631.63 | N13: =N12+M13 -> -77488.62
A14: 12 | B14: =ROUND(B13*(1.3-(12-1)*0.008),0) -> 1776 | C14: =ROUND(C13*0.98+B14,0) -> 8147 | D14: =ROUND(C14*0.8,0) -> 6518 | E14: =ROUND(D14*$E$2,0) -> 326 | F14: =D14-E14 -> 6192 | G14: =E14*$G$2 -> 1467 | H14: =F14*$H$2 -> 5944.32 | I14: =F14*$I$2 -> 1300.32 | J14: =$J$2 -> 0 | K14: =SUM(G14:J14) -> 8711.64 | L14: =$L$2 -> 9582.6 | M14: =K14-L14 -> -870.96 | N14: =N13+M14 -> -78359.58
A15: 13 | B15: =ROUND(B14*(1.3-(13-1)*0.008),0) -> 2138 | C15: =ROUND(C14*0.98+B15,0) -> 10122 | D15: =ROUND(C15*0.8,0) -> 8098 | E15: =ROUND(D15*$E$2,0) -> 405 | F15: =D15-E15 -> 7693 | G15: =E15*$G$2 -> 1822.5 | H15: =F15*$H$2 -> 7385.28 | I15: =F15*$I$2 -> 1615.53 | J15: =$J$2 -> 0 | K15: =SUM(G15:J15) -> 10823.31 | L15: =$L$2 -> 9582.6 | M15: =K15-L15 -> 1240.71 | N15: =N14+M15 -> -77118.87
A16: 14 | B16: =ROUND(B15*(1.3-(14-1)*0.008),0) -> 2557 | C16: =ROUND(C15*0.98+B16,0) -> 12477 | D16: =ROUND(C16*0.8,0) -> 9982 | E16: =ROUND(D16*$E$2,0) -> 499 | F16: =D16-E16 -> 9483 | G16: =E16*$G$2 -> 2245.5 | H16: =F16*$H$2 -> 9103.68 | I16: =F16*$I$2 -> 1991.43 | J16: =$J$2 -> 0 | K16: =SUM(G16:J16) -> 13340.61 | L16: =$L$2 -> 9582.6 | M16: =K16-L16 -> 3758.01 | N16: =N15+M16 -> -73360.86
A17: 15 | B17: =ROUND(B16*(1.3-(15-1)*0.008),0) -> 3038 | C17: =ROUND(C16*0.98+B17,0) -> 15265 | D17: =ROUND(C17*0.8,0) -> 12212 | E17: =ROUND(D17*$E$2,0) -> 611 | F17: =D17-E17 -> 11601 | G17: =E17*$G$2 -> 2749.5 | H17: =F17*$H$2 -> 11136.96 | I17: =F17*$I$2 -> 2436.21 | J17: =$J$2 -> 0 | K17: =SUM(G17:J17) -> 16322.67 | L17: =$L$2 -> 9582.6 | M17: =K17-L17 -> 6740.07 | N17: =N16+M17 -> -66620.79
A18: 16 | B18: =ROUND(B17*(1.3-(16-1)*0.008),0) -> 3585 | C18: =ROUND(C17*0.98+B18,0) -> 18545 | D18: =ROUND(C18*0.8,0) -> 14836 | E18: =ROUND(D18*$E$2,0) -> 742 | F18: =D18-E18 -> 14094 | G18: =E18*$G$2 -> 3339 | H18: =F18*$H$2 -> 13530.24 | I18: =F18*$I$2 -> 2959.74 | J18: =$J$2 -> 0 | K18: =SUM(G18:J18) -> 19828.98 | L18: =$L$2 -> 9582.6 | M18: =K18-L18 -> 10246.38 | N18: =N17+M18 -> -56374.41
A19: 17 | B19: =ROUND(B18*(1.3-(17-1)*0.008),0) -> 4202 | C19: =ROUND(C18*0.98+B19,0) -> 22376 | D19: =ROUND(C19*0.8,0) -> 17901 | E19: =ROUND(D19*$E$2,0) -> 895 | F19: =D19-E19 -> 17006 | G19: =E19*$G$2 -> 4027.5 | H19: =F19*$H$2 -> 16325.76 | I19: =F19*$I$2 -> 3571.26 | J19: =$J$2 -> 0 | K19: =SUM(G19:J19) -> 23924.52 | L19: =$L$2 -> 9582.6 | M19: =K19-L19 -> 14341.92 | N19: =N18+M19 -> -42032.49
A20: 18 | B20: =ROUND(B19*(1.3-(18-1)*0.008),0) -> 4891 | C20: =ROUND(C19*0.98+B20,0) -> 26819 | D20: =ROUND(C20*0.8,0) -> 21455 | E20: =ROUND(D20*$E$2,0) -> 1073 | F20: =D20-E20 -> 20382 | G20: =E20*$G$2 -> 4828.5 | H20: =F20*$H$2 -> 19566.72 | I20: =F20*$I$2 -> 4280.22 | J20: =$J$2 -> 0 | K20: =SUM(G20:J20) -> 28675.44 | L20: =$L$2 -> 9582.6 | M20: =K20-L20 -> 19092.84 | N20: =N19+M20 -> -22939.65
A21: 19 | B21: =ROUND(B20*(1.3-(19-1)*0.008),0) -> 5654 | C21: =ROUND(C20*0.98+B21,0) -> 31937 | D21: =ROUND(C21*0.8,0) -> 25550 | E21: =ROUND(D21*$E$2,0) -> 1278 | F21: =D21-E21 -> 24272 | G21: =E21*$G$2 -> 5751 | H21: =F21*$H$2 -> 23301.12 | I21: =F21*$I$2 -> 5097.12 | J21: =$J$2 -> 0 | K21: =SUM(G21:J21) -> 34149.24 | L21: =$L$2 -> 9582.6 | M21: =K21-L21 -> 24566.64 | N21: =N20+M21 -> 1626.99
A22: 20 | B22: =ROUND(B21*(1.3-(20-1)*0.008),0) -> 6491 | C22: =ROUND(C21*0.98+B22,0) -> 37789 | D22: =ROUND(C22*0.8,0) -> 30231 | E22: =ROUND(D22*$E$2,0) -> 1512 | F22: =D22-E22 -> 28719 | G22: =E22*$G$2 -> 6804 | H22: =F22*$H$2 -> 27570.24 | I22: =F22*$I$2 -> 6030.99 | J22: =$J$2 -> 0 | K22: =SUM(G22:J22) -> 40405.23 | L22: =$L$2 -> 9582.6 | M22: =K22-L22 -> 30822.63 | N22: =N21+M22 -> 32449.62
A23: 21 | B23: =ROUND(B22*(1.3-(21-1)*0.008),0) -> 7400 | C23: =ROUND(C22*0.98+B23,0) -> 44433 | D23: =ROUND(C23*0.8,0) -> 35546 | E23: =ROUND(D23*$E$2,0) -> 1777 | F23: =D23-E23 -> 33769 | G23: =E23*$G$2 -> 7996.5 | H23: =F23*$H$2 -> 32418.24 | I23: =F23*$I$2 -> 7091.49 | J23: =$J$2 -> 0 | K23: =SUM(G23:J23) -> 47506.23 | L23: =$L$2 -> 9582.6 | M23: =K23-L23 -> 37923.63 | N23: =N22+M23 -> 70373.25
A24: 22 | B24: =ROUND(B23*(1.3-(22-1)*0.008),0) -> 8377 | C24: =ROUND(C23*0.98+B24,0) -> 51921 | D24: =ROUND(C24*0.8,0) -> 41537 | E24: =ROUND(D24*$E$2,0) -> 2077 | F24: =D24-E24 -> 39460 | G24: =E24*$G$2 -> 9346.5 | H24: =F24*$H$2 -> 37881.6 | I24: =F24*$I$2 -> 8286.6 | J24: =$J$2 -> 0 | K24: =SUM(G24:J24) -> 55514.7 | L24: =$L$2 -> 9582.6 | M24: =K24-L24 -> 45932.1 | N24: =N23+M24 -> 116305.35
A25: 23 | B25: =ROUND(B24*(1.3-(23-1)*0.008),0) -> 9416 | C25: =ROUND(C24*0.98+B25,0) -> 60299 | D25: =ROUND(C25*0.8,0) -> 48239 | E25: =ROUND(D25*$E$2,0) -> 2412 | F25: =D25-E25 -> 45827 | G25: =E25*$G$2 -> 10854 | H25: =F25*$H$2 -> 43993.92 | I25: =F25*$I$2 -> 9623.67 | J25: =$J$2 -> 0 | K25: =SUM(G25:J25) -> 64471.59 | L25: =$L$2 -> 9582.6 | M25: =K25-L25 -> 54888.99 | N25: =N24+M25 -> 171194.34
A26: 24 | B26: =ROUND(B25*(1.3-(24-1)*0.008),0) -> 10508 | C26: =ROUND(C25*0.98+B26,0) -> 69601 | D26: =ROUND(C26*0.8,0) -> 55681 | E26: =ROUND(D26*$E$2,0) -> 2784 | F26: =D26-E26 -> 52897 | G26: =E26*$G$2 -> 12528 | H26: =F26*$H$2 -> 50781.12 | I26: =F26*$I$2 -> 11108.37 | J26: =$J$2 -> 0 | K26: =SUM(G26:J26) -> 74417.49 | L26: =$L$2 -> 9582.6 | M26: =K26-L26 -> 64834.89 | N26: =N25+M26 -> 236029.23
A27: GESAMT | B27: =SUM(B3:B26) -> 76926 | C27: =C26 -> 69601 | D27: =D26 -> 55681 | E27: =E26 -> 2784 | F27: =F26 -> 52897 | G27: =SUM(G3:G26) -> 78462 | H27: =SUM(H3:H26) -> 317989.44 | I27: =SUM(I3:I26) -> 69560.19 | J27: =SUM(J3:J26) -> 0 | K27: =SUM(K3:K26) -> 466011.63 | L27: =SUM(L3:L26) -> 229982.4 | M27: =SUM(M3:M26) -> 236029.23 | N27: =N26 -> 236029.23
A29: Break-Even Monat: | B29: =IFERROR(MATCH(TRUE(),INDEX(M3:M26>0,0),0),"Nicht in 24 Mon.") -> 13

Sheet Szenarien
A1: SZENARIO-VERGLEICH | B1: Pessimistisch | C1: Realistisch | D1: Optimistisch
A2: Conversion Rate | B2: 0.03 | C2: 0.05 | D2: 0.08
A3: Abo-Preis (€/Monat) | B3: 3.99 | C3: 4.5 | D3: 5.99
A4: Nutzer nach 12 Monaten | B4: 3000 | C4: 8000 | D4: 20000
A5: Nutzer nach 24 Monaten | B5: 8000 | C5: 25000 | D5: 80000
A6: Monatl. Churn Rate | B6: 0.05 | C6: 0.03 | D6: 0.02
A8: ERGEBNIS NACH 12 MONATEN
A9: Aktive Nutzer (80%) | B9: =ROUND(B4*0.8,0) -> 2400 | C9: =ROUND(C4*0.8,0) -> 6400 | D9: =ROUND(D4*0.8,0) -> 16000
A10: Ø Erlös pro Nutzer/Monat (€) | B10: =B2*B3 + (1-B2)*(Erlösmodell!C5*Erlösmodell!C6 + Erlösmodell!C7*Erlösmodell!C8/1000) -> 1.2546 | C10: =C2*C3 + (1-C2)*(Erlösmodell!C5*Erlösmodell!C6 + Erlösmodell!C7*Erlösmodell!C8/1000) -> 1.3365 | D10: =D2*D3 + (1-D2)*(Erlösmodell!C5*Erlösmodell!C6 + Erlösmodell!C7*Erlösmodell!C8/1000) -> 1.5556
A11: Monatsumsatz (€) | B11: =B9*B10 -> 3011.04 | C11: =C9*C10 -> 8553.6 | D11: =D9*D10 -> 24889.6
A12: Kosten p.m. (2 Gründer) | B12: ='2 Gründer'!B45 -> 9582.6 | C12: ='2 Gründer'!B45 -> 9582.6 | D12: ='2 Gründer'!B45 -> 9582.6
A13: Monatl. Gewinn/Verlust | B13: =B11-B12 -> -6571.56 | C13: =C11-C12 -> -1029 | D13: =D11-D12 -> 15307
A15: ERGEBNIS NACH 24 MONATEN
A16: Aktive Nutzer (80%) | B16: =ROUND(B5*0.8,0) -> 6400 | C16: =ROUND(C5*0.8,0) -> 20000 | D16: =ROUND(D5*0.8,0) -> 64000
A17: Monatsumsatz (€) | B17: =B16*B10 -> 8029.44 | C17: =C16*C10 -> 26730 | D17: =D16*D10 -> 99558.4
A18: Monatl. Gewinn/Verlust | B18: =B17-B12 -> -1553.16 | C18: =C17-C12 -> 17147.4 | D18: =D17-D12 -> 89975.8
A20: Benötigte Nutzer für Break-Even | B20: =ROUNDUP(B12/B10,0) -> 7638 | C20: =ROUNDUP(C12/C10,0) -> 7170 | D20: =ROUNDUP(D12/D10,0) -> 6161
